<mujoco model="robot">
        
  <compiler angle="radian" autolimits="true" />
        
  <option integrator="implicit" timestep="0.002" cone="pyramidal" solver="Newton" />
        
  <worldbody>
                
    <body name="main_plate_v3_1" pos="0 0 0.1">
      <freejoint/>
      <inertial fullinertia="9.25e-06 1.727e-05 2.415e-05 -0.0 2.38e-06 0.0" pos="-0.0520986918755481 2.319349956536598e-10 0.0019025856309235877" mass="0.025394005829932346" />
                        
      <body name="camera_plate_v1_1">
                                
        <inertial fullinertia="5.8e-07 6.4e-07 9.5e-07 0.0 5e-08 0.0" pos="-0.00109472732732795 2.9481332664005324e-09 0.0066766458202167644" mass="0.007015333441506587" />
                                
        <body name="ball_wheel_v1_1">
                                        
          <inertial fullinertia="1.71e-06 1.71e-06 1.71e-06 -0.0 0.0 -0.0" pos="2.2019546309460777e-19 8.881784197001253e-18 -4.163336342344337e-18" mass="0.03879238608652743" />
                                        
          <joint name="Revolute 4_joint" type="ball" pos="-0.0 0.0 -0.0" />
                                      
          <geom pos="-0.0 -0.052195 -0.0025" quat="0.0 0.0 0.0 1.0" material="Stainless_Steel_-_Satin" mesh="ball_wheel_v1_1_mesh" class="visual" />
                    
          <geom pos="-0.0 -0.052195 -0.0025" quat="0.0 0.0 0.0 1.0" mesh="ball_wheel_v1_1_mesh" class="collision" />
                  
        </body>
                                
        <body name="camera_v1_1">
          <camera name="cam" pos="0.03 0 0.0215" euler="1.56 -1.36 0"  fovy="90"  resolution="500 500"/>
                                        
          <inertial fullinertia="1.182e-05 2.295e-05 2.253e-05 1.4e-07 2.44e-06 -8e-08" pos="0.008939511053923061 7.874321397218462e-05 0.02597546374124492" mass="0.08553411992895192" />
                                        
          <geom pos="-0.023405 -0.029036 -0.025415" quat="0.703574 0.070593 0.070593 0.703574" mesh="camera_v1_1_mesh_0" material="Glass_-_Heavy_Color" class="visual" />
                    
          <geom pos="-0.023405 -0.029036 -0.025415" quat="0.703574 0.070593 0.070593 0.703574" mesh="camera_v1_1_mesh_1" material="Steel_-_Satin" class="visual" />
                    
          <geom pos="-0.023405 -0.029036 -0.025415" quat="0.703574 0.070593 0.070593 0.703574" mesh="camera_v1_1_mesh_0" class="collision" />
                    
          <geom pos="-0.023405 -0.029036 -0.025415" quat="0.703574 0.070593 0.070593 0.703574" mesh="camera_v1_1_mesh_1" class="collision" />
                  
        </body>
                                
        <geom pos="-0.008305 -0.024005 -0.0445" quat="0.0 0.0 0.0 1.0" material="PA_12_-_Nylon_-_PA_603-CF_(with_EOS_P_3D_Printers)" mesh="camera_plate_v1_1_mesh" class="visual" />
                
        <!-- <geom pos="-0.008305 -0.024005 -0.0445" quat="0.0 0.0 0.0 1.0" mesh="camera_plate_v1_1_mesh" class="collision" /> -->
              
      </body>
                        
      <body name="motor_v1_1">
                                
        <inertial fullinertia="3.399e-05 4.059e-05 5.146e-05 -5.53e-06 -0.0 -0.0" pos="-0.10069792270987482 -0.016718535990259818 0.011950040611941897" mass="0.22728577731179683" />
                                
        <body name="wheel_v1_1">
                                        
          <inertial fullinertia="1.37e-06 2.58e-06 1.37e-06 -0.0 0.0 0.0" pos="-0.11269560520522001 -0.03927549067001272 0.01194995383001105" mass="0.00889310201596848" />
                                        
          <joint name="rw_joint" type="hinge" pos="-0.112696 -0.0369 0.01195" axis="0.0 1.0 -0.0" />
                                      
          <geom pos="-0.112696 -0.039241 0.01195" quat="0.0 -0.0 0.0 1.0" mesh="wheel_v1_1_mesh_0" material="Polymide_(Kapton)" class="visual" />
                    
          <geom pos="-0.112696 -0.039241 0.01195" quat="0.0 -0.0 0.0 1.0" mesh="wheel_v1_1_mesh_1" material="Rubber_-_Soft" class="visual" />
                    
          <geom pos="-0.112696 -0.039241 0.01195" quat="0.0 -0.0 0.0 1.0" mesh="wheel_v1_1_mesh_0" class="collision" />
                    
          <geom pos="-0.112696 -0.039241 0.01195" quat="0.0 -0.0 0.0 1.0" mesh="wheel_v1_1_mesh_1" class="collision" />
                  
        </body>
                                
        <geom pos="-0.112696 -0.0 0.01195" quat="0.5 0.5 -0.5 0.5" mesh="motor_v1_1_mesh_0" material="Aluminum_-_Polished" class="visual" />
                
        <geom pos="-0.112696 -0.0 0.01195" quat="0.5 0.5 -0.5 0.5" mesh="motor_v1_1_mesh_1" material="Aluminum_-_Anodized_Glossy_(Grey)" class="visual" />
                
        <!-- <geom pos="-0.112696 -0.0 0.01195" quat="0.5 0.5 -0.5 0.5" mesh="motor_v1_1_mesh_0" class="collision" />
                
        <geom pos="-0.112696 -0.0 0.01195" quat="0.5 0.5 -0.5 0.5" mesh="motor_v1_1_mesh_1" class="collision" /> -->
              
      </body>
                        
      <body name="motor_v1_2">
                                
        <inertial fullinertia="3.399e-05 4.059e-05 5.146e-05 5.53e-06 0.0 -0.0" pos="-0.10069792270987488 0.018718535990259834 0.011899959388058576" mass="0.22728577731179683" />
                                
        <body name="wheel_v1_2">
                                        
          <inertial fullinertia="1.37e-06 2.58e-06 1.37e-06 0.0 -0.0 0.0" pos="-0.11269560520522004 0.04127549067001274 0.011900046169989425" mass="0.00889310201596848" />
                                        
          <joint name="lw_joint" type="hinge" pos="-0.112696 0.0389 0.0119"  axis="-0.0 1.0 -0.0" />
                                      
          <geom pos="-0.112696 0.041241 0.0119" quat="-0.0 -0.0 1.0 -0.0" mesh="wheel_v1_2_mesh_0" material="Polymide_(Kapton)" class="visual" />
                    
          <geom pos="-0.112696 0.041241 0.0119" quat="-0.0 -0.0 1.0 -0.0" mesh="wheel_v1_2_mesh_1" material="Rubber_-_Soft" class="visual" />
                    
          <geom pos="-0.112696 0.041241 0.0119" quat="-0.0 -0.0 1.0 -0.0" mesh="wheel_v1_2_mesh_0" class="collision" />
                    
          <geom pos="-0.112696 0.041241 0.0119" quat="-0.0 -0.0 1.0 -0.0" mesh="wheel_v1_2_mesh_1" class="collision" />
                  
        </body>
                                
        <geom pos="-0.112696 0.002 0.0119" quat="0.5 -0.5 0.5 0.5" mesh="motor_v1_2_mesh_0" material="Aluminum_-_Polished" class="visual" />
                
        <geom pos="-0.112696 0.002 0.0119" quat="0.5 -0.5 0.5 0.5" mesh="motor_v1_2_mesh_1" material="Aluminum_-_Anodized_Glossy_(Grey)" class="visual" />
                
        <!-- <geom pos="-0.112696 0.002 0.0119" quat="0.5 -0.5 0.5 0.5" mesh="motor_v1_2_mesh_0" class="collision" />
                
        <geom pos="-0.112696 0.002 0.0119" quat="0.5 -0.5 0.5 0.5" mesh="motor_v1_2_mesh_1" class="collision" /> -->
              
      </body>
                        
      <body name="controller_v2_1">
                                
        <inertial fullinertia="0.0001402 7.78e-05 0.00015104 1.11e-06 1e-08 -3.499e-05" pos="-0.048822788167997164 0.023546379220334746 0.03131983420637534" mass="0.13912139089522532" />
                                
        <body name="battery_v1_1">
                                        
          <inertial fullinertia="0.00011244 4.229e-05 0.00014039 0.0 0.0 4.6e-07" pos="-0.048686277228095404 -0.002632283409780784 0.015716066126842797" mass="0.2846841852951556" />
                                        
          <geom pos="-0.058686 -0.035 0.01625" quat="0.5 -0.5 -0.5 -0.5" mesh="battery_v1_1_mesh_0" material="Opaque(25,25,25)" class="visual" />
                    
          <geom pos="-0.058686 -0.035 0.01625" quat="0.5 -0.5 -0.5 -0.5" mesh="battery_v1_1_mesh_1" material="Opaque(245,245,246)" class="visual" />
                    
          <geom pos="-0.058686 -0.035 0.01625" quat="0.5 -0.5 -0.5 -0.5" mesh="battery_v1_1_mesh_2" material="Steel_-_Satin" class="visual" />
                    
          <geom pos="-0.058686 -0.035 0.01625" quat="0.5 -0.5 -0.5 -0.5" mesh="battery_v1_1_mesh_0" class="collision" />
                    
          <geom pos="-0.058686 -0.035 0.01625" quat="0.5 -0.5 -0.5 -0.5" mesh="battery_v1_1_mesh_1" class="collision" />
                    
          <geom pos="-0.058686 -0.035 0.01625" quat="0.5 -0.5 -0.5 -0.5" mesh="battery_v1_1_mesh_2" class="collision" />
                  
        </body>
                                
        <geom pos="-0.051804 0.126691 -0.0512" quat="0.707107 0.0 0.0 0.707107" mesh="controller_v2_1_mesh_0" material="Carbon_Fiber_-_Plain" class="visual" />
                
        <geom pos="-0.051804 0.126691 -0.0512" quat="0.707107 0.0 0.0 0.707107" mesh="controller_v2_1_mesh_1" material="Brass_-_Polished" class="visual" />
                
        <geom pos="-0.051804 0.126691 -0.0512" quat="0.707107 0.0 0.0 0.707107" mesh="controller_v2_1_mesh_2" material="Opaque(247,224,153)" class="visual" />
                
        <geom pos="-0.051804 0.126691 -0.0512" quat="0.707107 0.0 0.0 0.707107" mesh="controller_v2_1_mesh_3" material="Opaque(229,229,229)" class="visual" />
                
        <geom pos="-0.051804 0.126691 -0.0512" quat="0.707107 0.0 0.0 0.707107" mesh="controller_v2_1_mesh_4" material="Opaque(10,125,181)" class="visual" />
                
        <geom pos="-0.051804 0.126691 -0.0512" quat="0.707107 0.0 0.0 0.707107" mesh="controller_v2_1_mesh_5" material="Opaque(247,66,66)" class="visual" />
                
        <geom pos="-0.051804 0.126691 -0.0512" quat="0.707107 0.0 0.0 0.707107" mesh="controller_v2_1_mesh_6" material="Opaque(153,153,153)" class="visual" />
                
        <geom pos="-0.051804 0.126691 -0.0512" quat="0.707107 0.0 0.0 0.707107" mesh="controller_v2_1_mesh_7" material="Opaque(255,0,128)" class="visual" />
                
        <geom pos="-0.051804 0.126691 -0.0512" quat="0.707107 0.0 0.0 0.707107" mesh="controller_v2_1_mesh_8" material="Opaque(255,43,43)" class="visual" />
                
        <geom pos="-0.051804 0.126691 -0.0512" quat="0.707107 0.0 0.0 0.707107" mesh="controller_v2_1_mesh_9" material="Opaque(137,89,86)" class="visual" />
                
        <geom pos="-0.051804 0.126691 -0.0512" quat="0.707107 0.0 0.0 0.707107" mesh="controller_v2_1_mesh_10" material="Opaque(145,145,150)" class="visual" />
                
        <geom pos="-0.051804 0.126691 -0.0512" quat="0.707107 0.0 0.0 0.707107" mesh="controller_v2_1_mesh_11" material="Opaque(76,76,76)" class="visual" />
                
        <geom pos="-0.051804 0.126691 -0.0512" quat="0.707107 0.0 0.0 0.707107" mesh="controller_v2_1_mesh_12" material="Opaque(252,251,255)" class="visual" />
                
        <geom pos="-0.051804 0.126691 -0.0512" quat="0.707107 0.0 0.0 0.707107" mesh="controller_v2_1_mesh_13" material="Opaque(255,255,255)" class="visual" />
                
        <geom pos="-0.051804 0.126691 -0.0512" quat="0.707107 0.0 0.0 0.707107" mesh="controller_v2_1_mesh_14" material="Opaque(255,193,144)" class="visual" />
                
        <geom pos="-0.051804 0.126691 -0.0512" quat="0.707107 0.0 0.0 0.707107" mesh="controller_v2_1_mesh_15" material="Plastic_-_Glossy_(Black)" class="visual" />
                
        <geom pos="-0.051804 0.126691 -0.0512" quat="0.707107 0.0 0.0 0.707107" mesh="controller_v2_1_mesh_16" material="Opaque(255,140,0)" class="visual" />
                
        <geom pos="-0.051804 0.126691 -0.0512" quat="0.707107 0.0 0.0 0.707107" mesh="controller_v2_1_mesh_17" material="Opaque(87,214,105)" class="visual" />
                
        <geom pos="-0.051804 0.126691 -0.0512" quat="0.707107 0.0 0.0 0.707107" mesh="controller_v2_1_mesh_18" material="Opaque(202,209,238)" class="visual" />
                
        <geom pos="-0.051804 0.126691 -0.0512" quat="0.707107 0.0 0.0 0.707107" mesh="controller_v2_1_mesh_19" material="Opaque(255,255,0)" class="visual" />
                
       
      </body>
                      
      <geom pos="-0.10369 -0.024005 0.01195" quat="0.0 0.0 -0.0 1.0" material="Carbon_Fiber_-_Plain" mesh="main_plate_v3_1_mesh" class="visual" />
            
      <!-- <geom pos="-0.10369 -0.024005 0.01195" quat="0.0 0.0 -0.0 1.0" mesh="main_plate_v3_1_mesh" class="collision" /> -->
          
    </body>
            
  </worldbody>
        
  <default>
                
    <default class="visual">
                        
      <geom group="2" type="mesh" contype="0" conaffinity="0" />
                    
    </default>
                
    <default class="collision">
                        
      <geom group="3" type="mesh" />
                    
    </default>
            
  </default>
        
  <asset>
        
    <material name="Stainless_Steel_-_Satin" specular="0.5" shininess="0.5" rgba="0.796078 0.796078 0.796078 1.0" />
        
    <mesh name="ball_wheel_v1_1_mesh" file="ball_wheel_v1_1_mesh.obj" />
        
    <material name="Steel_-_Satin" specular="0.5" shininess="0.5" rgba="0.627451 0.627451 0.627451 1.0" />
        
    <material name="Opaque(245,245,246)" specular="0.5" shininess="0.5" rgba="0.960784 0.960784 0.964706 1.0" />
        
    <material name="Opaque(25,25,25)" specular="0.5" shininess="0.5" rgba="0.098039 0.098039 0.098039 1.0" />
        
    <mesh name="battery_v1_1_mesh_0" file="battery_v1_1_mesh_0.obj" />
        
    <mesh name="battery_v1_1_mesh_1" file="battery_v1_1_mesh_1.obj" />
        
    <mesh name="battery_v1_1_mesh_2" file="battery_v1_1_mesh_2.obj" />
        
    <material name="PA_12_-_Nylon_-_PA_603-CF_(with_EOS_P_3D_Printers)" specular="0.5" shininess="0.5" rgba="0.247059 0.247059 0.247059 1.0" />
        
    <mesh name="camera_plate_v1_1_mesh" file="camera_plate_v1_1_mesh.obj" />
        
    <material name="Glass_-_Heavy_Color" specular="0.5" shininess="0.5" rgba="0.098039 0.098039 0.098039 0.7" />
        
    <mesh name="camera_v1_1_mesh_0" file="camera_v1_1_mesh_0.obj" />
        
    <mesh name="camera_v1_1_mesh_1" file="camera_v1_1_mesh_1.obj" />
        
    <material name="Opaque(255,255,0)" specular="0.5" shininess="0.5" rgba="1.000000 1.000000 0.000000 1.0" />
        
    <material name="Opaque(202,209,238)" specular="0.5" shininess="0.5" rgba="0.792157 0.819608 0.933333 1.0" />
        
    <material name="Opaque(87,214,105)" specular="0.5" shininess="0.5" rgba="0.341176 0.839216 0.411765 1.0" />
        
    <material name="Opaque(255,140,0)" specular="0.5" shininess="0.5" rgba="1.000000 0.549020 0.000000 1.0" />
        
    <material name="Plastic_-_Glossy_(Black)" specular="0.5" shininess="0.5" rgba="0.098039 0.098039 0.098039 1.0" />
        
    <material name="Opaque(255,193,144)" specular="0.5" shininess="0.5" rgba="1.000000 0.756863 0.564706 1.0" />
        
    <material name="Opaque(255,255,255)" specular="0.5" shininess="0.5" rgba="1.000000 1.000000 1.000000 1.0" />
        
    <material name="Opaque(252,251,255)" specular="0.5" shininess="0.5" rgba="0.988235 0.984314 1.000000 1.0" />
        
    <material name="Opaque(76,76,76)" specular="0.5" shininess="0.5" rgba="0.298039 0.298039 0.298039 1.0" />
        
    <material name="Opaque(145,145,150)" specular="0.5" shininess="0.5" rgba="0.568627 0.568627 0.588235 1.0" />
        
    <material name="Opaque(137,89,86)" specular="0.5" shininess="0.5" rgba="0.537255 0.349020 0.337255 1.0" />
        
    <material name="Opaque(255,43,43)" specular="0.5" shininess="0.5" rgba="1.000000 0.168627 0.168627 1.0" />
        
    <material name="Opaque(255,0,128)" specular="0.5" shininess="0.5" rgba="1.000000 0.000000 0.501961 1.0" />
        
    <material name="Opaque(153,153,153)" specular="0.5" shininess="0.5" rgba="0.600000 0.600000 0.600000 1.0" />
        
    <material name="Opaque(247,66,66)" specular="0.5" shininess="0.5" rgba="0.968627 0.258824 0.258824 1.0" />
        
    <material name="Opaque(10,125,181)" specular="0.5" shininess="0.5" rgba="0.039216 0.490196 0.709804 1.0" />
        
    <material name="Opaque(229,229,229)" specular="0.5" shininess="0.5" rgba="0.898039 0.898039 0.898039 1.0" />
        
    <material name="Opaque(247,224,153)" specular="0.5" shininess="0.5" rgba="0.968627 0.878431 0.600000 1.0" />
        
    <material name="Brass_-_Polished" specular="0.5" shininess="0.5" rgba="0.952941 0.796078 0.486275 1.0" />
        
    <material name="Carbon_Fiber_-_Plain" specular="0.5" shininess="0.5" rgba="0.098039 0.098039 0.098039 1.0" />
        
    <mesh name="controller_v2_1_mesh_0" file="controller_v2_1_mesh_0.obj" />
        
    <mesh name="controller_v2_1_mesh_1" file="controller_v2_1_mesh_1.obj" />
        
    <mesh name="controller_v2_1_mesh_2" file="controller_v2_1_mesh_2.obj" />
        
    <mesh name="controller_v2_1_mesh_3" file="controller_v2_1_mesh_3.obj" />
        
    <mesh name="controller_v2_1_mesh_4" file="controller_v2_1_mesh_4.obj" />
        
    <mesh name="controller_v2_1_mesh_5" file="controller_v2_1_mesh_5.obj" />
        
    <mesh name="controller_v2_1_mesh_6" file="controller_v2_1_mesh_6.obj" />
        
    <mesh name="controller_v2_1_mesh_7" file="controller_v2_1_mesh_7.obj" />
        
    <mesh name="controller_v2_1_mesh_8" file="controller_v2_1_mesh_8.obj" />
        
    <mesh name="controller_v2_1_mesh_9" file="controller_v2_1_mesh_9.obj" />
        
    <mesh name="controller_v2_1_mesh_10" file="controller_v2_1_mesh_10.obj" />
        
    <mesh name="controller_v2_1_mesh_11" file="controller_v2_1_mesh_11.obj" />
        
    <mesh name="controller_v2_1_mesh_12" file="controller_v2_1_mesh_12.obj" />
        
    <mesh name="controller_v2_1_mesh_13" file="controller_v2_1_mesh_13.obj" />
        
    <mesh name="controller_v2_1_mesh_14" file="controller_v2_1_mesh_14.obj" />
        
    <mesh name="controller_v2_1_mesh_15" file="controller_v2_1_mesh_15.obj" />
        
    <mesh name="controller_v2_1_mesh_16" file="controller_v2_1_mesh_16.obj" />
        
    <mesh name="controller_v2_1_mesh_17" file="controller_v2_1_mesh_17.obj" />
        
    <mesh name="controller_v2_1_mesh_18" file="controller_v2_1_mesh_18.obj" />
        
    <mesh name="controller_v2_1_mesh_19" file="controller_v2_1_mesh_19.obj" />
        
    <mesh name="main_plate_v3_1_mesh" file="main_plate_v3_1_mesh.obj" />
        
    <material name="Aluminum_-_Anodized_Glossy_(Grey)" specular="0.5" shininess="0.5" rgba="0.266667 0.266667 0.266667 1.0" />
        
    <material name="Aluminum_-_Polished" specular="0.5" shininess="0.5" rgba="0.960784 0.960784 0.964706 1.0" />
        
    <mesh name="motor_v1_1_mesh_0" file="motor_v1_1_mesh_0.obj" />
        
    <mesh name="motor_v1_1_mesh_1" file="motor_v1_1_mesh_1.obj" />
        
    <mesh name="motor_v1_2_mesh_0" file="motor_v1_2_mesh_0.obj" />
        
    <mesh name="motor_v1_2_mesh_1" file="motor_v1_2_mesh_1.obj" />
        
    <material name="Rubber_-_Soft" specular="0.5" shininess="0.5" rgba="0.152941 0.152941 0.152941 1.0" />
        
    <material name="Polymide_(Kapton)" specular="0.5" shininess="0.5" rgba="0.784314 0.556863 0.027451 1.0" />
        
    <mesh name="wheel_v1_1_mesh_0" file="wheel_v1_1_mesh_0.obj" />
        
    <mesh name="wheel_v1_1_mesh_1" file="wheel_v1_1_mesh_1.obj" />
        
    <mesh name="wheel_v1_2_mesh_0" file="wheel_v1_2_mesh_0.obj" />
        
    <mesh name="wheel_v1_2_mesh_1" file="wheel_v1_2_mesh_1.obj" />
      
  </asset>
    
<equality />
<actuator>
<velocity name="rw" joint="rw_joint"  ctrlrange="-100 100" forcerange="-3.5 3.5" kv="0.01" />
<velocity name="lw" ctrlrange="-100 100" joint="lw_joint" forcerange="-3.5 3.5"  kv="0.01" />
</actuator></mujoco>